
2024-08-03 16:56:06 [ERROR] DashboardView ERROR: Database returned an invalid datetime value. Are time zone definitions for your database installed? ret:None

2024-08-03 16:56:06 [ERROR] DashboardView ERROR: Database returned an invalid datetime value. Are time zone definitions for your database installed? ret:None

2024-08-03 16:56:06 [ERROR] 
Traceback (most recent call last):
  File "/data/xadmin/py312/lib64/python3.12/site-packages/rest_framework/views.py", line 506, in dispatch
    response = handler(request, *args, **kwargs)
               ^^^^^^^^^^^^^^^^^^^^^^^^^^^^^^^^^
  File "/data/xadmin/xadmin-server/system/views/dashboard.py", line 59, in user_registered_trend
    return ApiResponse(data=trend_info(self.filter_queryset(self.get_queryset()))[0])
                            ^^^^^^^^^^^^^^^^^^^^^^^^^^^^^^^^^^^^^^^^^^^^^^^^^^^^^
  File "/data/xadmin/xadmin-server/system/views/dashboard.py", line 27, in trend_info
    dict_count = {d.get('date').strftime('%m-%d'): d.get('count') for d in data_count}
                 ^^^^^^^^^^^^^^^^^^^^^^^^^^^^^^^^^^^^^^^^^^^^^^^^^^^^^^^^^^^^^^^^^^^^^
  File "/data/xadmin/py312/lib64/python3.12/site-packages/django/db/models/query.py", line 400, in __iter__
    self._fetch_all()
  File "/data/xadmin/py312/lib64/python3.12/site-packages/django/db/models/query.py", line 1928, in _fetch_all
    self._result_cache = list(self._iterable_class(self))
                         ^^^^^^^^^^^^^^^^^^^^^^^^^^^^^^^^
  File "/data/xadmin/py312/lib64/python3.12/site-packages/django/db/models/query.py", line 210, in __iter__
    for row in compiler.results_iter(
  File "/data/xadmin/py312/lib64/python3.12/site-packages/django/db/models/sql/compiler.py", line 1500, in apply_converters
    value = converter(value, expression, connection)
            ^^^^^^^^^^^^^^^^^^^^^^^^^^^^^^^^^^^^^^^^
  File "/data/xadmin/py312/lib64/python3.12/site-packages/django/db/models/functions/datetime.py", line 353, in convert_value
    raise ValueError(
ValueError: Database returned an invalid datetime value. Are time zone definitions for your database installed?

2024-08-03 16:56:06 [ERROR] DashboardView ERROR: Database returned an invalid datetime value. Are time zone definitions for your database installed? ret:None

2024-08-03 16:56:06 [ERROR] DashboardView ERROR: Database returned an invalid datetime value. Are time zone definitions for your database installed? ret:None

2024-08-03 16:56:06 [ERROR] DashboardView ERROR: Database returned an invalid datetime value. Are time zone definitions for your database installed? ret:None

2024-08-03 16:56:06 [ERROR] DashboardView ERROR: Database returned an invalid datetime value. Are time zone definitions for your database installed? ret:None

2024-08-03 16:56:06 [ERROR] DashboardView ERROR: Database returned an invalid datetime value. Are time zone definitions for your database installed? ret:None

2024-08-03 16:56:06 [ERROR] DashboardView ERROR: Database returned an invalid datetime value. Are time zone definitions for your database installed? ret:None

2024-08-03 16:56:06 [ERROR] 
Traceback (most recent call last):
  File "/data/xadmin/py312/lib64/python3.12/site-packages/rest_framework/views.py", line 506, in dispatch
    response = handler(request, *args, **kwargs)
               ^^^^^^^^^^^^^^^^^^^^^^^^^^^^^^^^^
  File "/data/xadmin/xadmin-server/system/views/dashboard.py", line 54, in user_total
    results, percent, count = trend_info(self.filter_queryset(self.get_queryset()), 7)
                              ^^^^^^^^^^^^^^^^^^^^^^^^^^^^^^^^^^^^^^^^^^^^^^^^^^^^^^^^
  File "/data/xadmin/xadmin-server/system/views/dashboard.py", line 27, in trend_info
    dict_count = {d.get('date').strftime('%m-%d'): d.get('count') for d in data_count}
                 ^^^^^^^^^^^^^^^^^^^^^^^^^^^^^^^^^^^^^^^^^^^^^^^^^^^^^^^^^^^^^^^^^^^^^
  File "/data/xadmin/py312/lib64/python3.12/site-packages/django/db/models/query.py", line 400, in __iter__
    self._fetch_all()
  File "/data/xadmin/py312/lib64/python3.12/site-packages/django/db/models/query.py", line 1928, in _fetch_all
    self._result_cache = list(self._iterable_class(self))
                         ^^^^^^^^^^^^^^^^^^^^^^^^^^^^^^^^
  File "/data/xadmin/py312/lib64/python3.12/site-packages/django/db/models/query.py", line 210, in __iter__
    for row in compiler.results_iter(
  File "/data/xadmin/py312/lib64/python3.12/site-packages/django/db/models/sql/compiler.py", line 1500, in apply_converters
    value = converter(value, expression, connection)
            ^^^^^^^^^^^^^^^^^^^^^^^^^^^^^^^^^^^^^^^^
  File "/data/xadmin/py312/lib64/python3.12/site-packages/django/db/models/functions/datetime.py", line 353, in convert_value
    raise ValueError(
ValueError: Database returned an invalid datetime value. Are time zone definitions for your database installed?

2024-08-03 16:56:06 [ERROR] 
Traceback (most recent call last):
  File "/data/xadmin/py312/lib64/python3.12/site-packages/rest_framework/views.py", line 506, in dispatch
    response = handler(request, *args, **kwargs)
               ^^^^^^^^^^^^^^^^^^^^^^^^^^^^^^^^^
  File "/data/xadmin/xadmin-server/system/views/dashboard.py", line 49, in user_login_total
    results, percent, count = trend_info(self.filter_queryset(self.get_queryset()), 7)
                              ^^^^^^^^^^^^^^^^^^^^^^^^^^^^^^^^^^^^^^^^^^^^^^^^^^^^^^^^
  File "/data/xadmin/xadmin-server/system/views/dashboard.py", line 27, in trend_info
    dict_count = {d.get('date').strftime('%m-%d'): d.get('count') for d in data_count}
                 ^^^^^^^^^^^^^^^^^^^^^^^^^^^^^^^^^^^^^^^^^^^^^^^^^^^^^^^^^^^^^^^^^^^^^
  File "/data/xadmin/py312/lib64/python3.12/site-packages/django/db/models/query.py", line 400, in __iter__
    self._fetch_all()
  File "/data/xadmin/py312/lib64/python3.12/site-packages/django/db/models/query.py", line 1928, in _fetch_all
    self._result_cache = list(self._iterable_class(self))
                         ^^^^^^^^^^^^^^^^^^^^^^^^^^^^^^^^
  File "/data/xadmin/py312/lib64/python3.12/site-packages/django/db/models/query.py", line 210, in __iter__
    for row in compiler.results_iter(
  File "/data/xadmin/py312/lib64/python3.12/site-packages/django/db/models/sql/compiler.py", line 1500, in apply_converters
    value = converter(value, expression, connection)
            ^^^^^^^^^^^^^^^^^^^^^^^^^^^^^^^^^^^^^^^^
  File "/data/xadmin/py312/lib64/python3.12/site-packages/django/db/models/functions/datetime.py", line 353, in convert_value
    raise ValueError(
ValueError: Database returned an invalid datetime value. Are time zone definitions for your database installed?

2024-08-03 16:56:06 [ERROR] 
Traceback (most recent call last):
  File "/data/xadmin/py312/lib64/python3.12/site-packages/rest_framework/views.py", line 506, in dispatch
    response = handler(request, *args, **kwargs)
               ^^^^^^^^^^^^^^^^^^^^^^^^^^^^^^^^^
  File "/data/xadmin/xadmin-server/system/views/dashboard.py", line 63, in user_login_trend
    return ApiResponse(data=trend_info(self.filter_queryset(self.get_queryset()))[0])
                            ^^^^^^^^^^^^^^^^^^^^^^^^^^^^^^^^^^^^^^^^^^^^^^^^^^^^^
  File "/data/xadmin/xadmin-server/system/views/dashboard.py", line 27, in trend_info
    dict_count = {d.get('date').strftime('%m-%d'): d.get('count') for d in data_count}
                 ^^^^^^^^^^^^^^^^^^^^^^^^^^^^^^^^^^^^^^^^^^^^^^^^^^^^^^^^^^^^^^^^^^^^^
  File "/data/xadmin/py312/lib64/python3.12/site-packages/django/db/models/query.py", line 400, in __iter__
    self._fetch_all()
  File "/data/xadmin/py312/lib64/python3.12/site-packages/django/db/models/query.py", line 1928, in _fetch_all
    self._result_cache = list(self._iterable_class(self))
                         ^^^^^^^^^^^^^^^^^^^^^^^^^^^^^^^^
  File "/data/xadmin/py312/lib64/python3.12/site-packages/django/db/models/query.py", line 210, in __iter__
    for row in compiler.results_iter(
  File "/data/xadmin/py312/lib64/python3.12/site-packages/django/db/models/sql/compiler.py", line 1500, in apply_converters
    value = converter(value, expression, connection)
            ^^^^^^^^^^^^^^^^^^^^^^^^^^^^^^^^^^^^^^^^
  File "/data/xadmin/py312/lib64/python3.12/site-packages/django/db/models/functions/datetime.py", line 353, in convert_value
    raise ValueError(
ValueError: Database returned an invalid datetime value. Are time zone definitions for your database installed?

2024-08-03 16:56:06 [ERROR] DashboardView ERROR: Database returned an invalid datetime value. Are time zone definitions for your database installed? ret:None

2024-08-03 16:56:06 [ERROR] DashboardView ERROR: Database returned an invalid datetime value. Are time zone definitions for your database installed? ret:None

2024-08-03 16:56:06 [ERROR] 
Traceback (most recent call last):
  File "/data/xadmin/py312/lib64/python3.12/site-packages/rest_framework/views.py", line 506, in dispatch
    response = handler(request, *args, **kwargs)
               ^^^^^^^^^^^^^^^^^^^^^^^^^^^^^^^^^
  File "/data/xadmin/xadmin-server/system/views/dashboard.py", line 67, in today_operate_total
    results, percent, count = trend_info(self.filter_queryset(self.get_queryset()), 7)
                              ^^^^^^^^^^^^^^^^^^^^^^^^^^^^^^^^^^^^^^^^^^^^^^^^^^^^^^^^
  File "/data/xadmin/xadmin-server/system/views/dashboard.py", line 27, in trend_info
    dict_count = {d.get('date').strftime('%m-%d'): d.get('count') for d in data_count}
                 ^^^^^^^^^^^^^^^^^^^^^^^^^^^^^^^^^^^^^^^^^^^^^^^^^^^^^^^^^^^^^^^^^^^^^
  File "/data/xadmin/py312/lib64/python3.12/site-packages/django/db/models/query.py", line 400, in __iter__
    self._fetch_all()
  File "/data/xadmin/py312/lib64/python3.12/site-packages/django/db/models/query.py", line 1928, in _fetch_all
    self._result_cache = list(self._iterable_class(self))
                         ^^^^^^^^^^^^^^^^^^^^^^^^^^^^^^^^
  File "/data/xadmin/py312/lib64/python3.12/site-packages/django/db/models/query.py", line 210, in __iter__
    for row in compiler.results_iter(
  File "/data/xadmin/py312/lib64/python3.12/site-packages/django/db/models/sql/compiler.py", line 1500, in apply_converters
    value = converter(value, expression, connection)
            ^^^^^^^^^^^^^^^^^^^^^^^^^^^^^^^^^^^^^^^^
  File "/data/xadmin/py312/lib64/python3.12/site-packages/django/db/models/functions/datetime.py", line 353, in convert_value
    raise ValueError(
ValueError: Database returned an invalid datetime value. Are time zone definitions for your database installed?

2024-08-03 16:56:22 [ERROR] DashboardView ERROR: Database returned an invalid datetime value. Are time zone definitions for your database installed? ret:None

2024-08-03 16:56:22 [ERROR] DashboardView ERROR: Database returned an invalid datetime value. Are time zone definitions for your database installed? ret:None

2024-08-03 16:56:22 [ERROR] DashboardView ERROR: Database returned an invalid datetime value. Are time zone definitions for your database installed? ret:None

2024-08-03 16:56:22 [ERROR] DashboardView ERROR: Database returned an invalid datetime value. Are time zone definitions for your database installed? ret:None

2024-08-03 16:56:22 [ERROR] 
Traceback (most recent call last):
  File "/data/xadmin/py312/lib64/python3.12/site-packages/rest_framework/views.py", line 506, in dispatch
    response = handler(request, *args, **kwargs)
               ^^^^^^^^^^^^^^^^^^^^^^^^^^^^^^^^^
  File "/data/xadmin/xadmin-server/system/views/dashboard.py", line 67, in today_operate_total
    results, percent, count = trend_info(self.filter_queryset(self.get_queryset()), 7)
                              ^^^^^^^^^^^^^^^^^^^^^^^^^^^^^^^^^^^^^^^^^^^^^^^^^^^^^^^^
  File "/data/xadmin/xadmin-server/system/views/dashboard.py", line 27, in trend_info
    dict_count = {d.get('date').strftime('%m-%d'): d.get('count') for d in data_count}
                 ^^^^^^^^^^^^^^^^^^^^^^^^^^^^^^^^^^^^^^^^^^^^^^^^^^^^^^^^^^^^^^^^^^^^^
  File "/data/xadmin/py312/lib64/python3.12/site-packages/django/db/models/query.py", line 400, in __iter__
    self._fetch_all()
  File "/data/xadmin/py312/lib64/python3.12/site-packages/django/db/models/query.py", line 1928, in _fetch_all
    self._result_cache = list(self._iterable_class(self))
                         ^^^^^^^^^^^^^^^^^^^^^^^^^^^^^^^^
  File "/data/xadmin/py312/lib64/python3.12/site-packages/django/db/models/query.py", line 210, in __iter__
    for row in compiler.results_iter(
  File "/data/xadmin/py312/lib64/python3.12/site-packages/django/db/models/sql/compiler.py", line 1500, in apply_converters
    value = converter(value, expression, connection)
            ^^^^^^^^^^^^^^^^^^^^^^^^^^^^^^^^^^^^^^^^
  File "/data/xadmin/py312/lib64/python3.12/site-packages/django/db/models/functions/datetime.py", line 353, in convert_value
    raise ValueError(
ValueError: Database returned an invalid datetime value. Are time zone definitions for your database installed?

2024-08-03 16:56:22 [ERROR] 
Traceback (most recent call last):
  File "/data/xadmin/py312/lib64/python3.12/site-packages/rest_framework/views.py", line 506, in dispatch
    response = handler(request, *args, **kwargs)
               ^^^^^^^^^^^^^^^^^^^^^^^^^^^^^^^^^
  File "/data/xadmin/xadmin-server/system/views/dashboard.py", line 49, in user_login_total
    results, percent, count = trend_info(self.filter_queryset(self.get_queryset()), 7)
                              ^^^^^^^^^^^^^^^^^^^^^^^^^^^^^^^^^^^^^^^^^^^^^^^^^^^^^^^^
  File "/data/xadmin/xadmin-server/system/views/dashboard.py", line 27, in trend_info
    dict_count = {d.get('date').strftime('%m-%d'): d.get('count') for d in data_count}
                 ^^^^^^^^^^^^^^^^^^^^^^^^^^^^^^^^^^^^^^^^^^^^^^^^^^^^^^^^^^^^^^^^^^^^^
  File "/data/xadmin/py312/lib64/python3.12/site-packages/django/db/models/query.py", line 400, in __iter__
    self._fetch_all()
  File "/data/xadmin/py312/lib64/python3.12/site-packages/django/db/models/query.py", line 1928, in _fetch_all
    self._result_cache = list(self._iterable_class(self))
                         ^^^^^^^^^^^^^^^^^^^^^^^^^^^^^^^^
  File "/data/xadmin/py312/lib64/python3.12/site-packages/django/db/models/query.py", line 210, in __iter__
    for row in compiler.results_iter(
  File "/data/xadmin/py312/lib64/python3.12/site-packages/django/db/models/sql/compiler.py", line 1500, in apply_converters
    value = converter(value, expression, connection)
            ^^^^^^^^^^^^^^^^^^^^^^^^^^^^^^^^^^^^^^^^
  File "/data/xadmin/py312/lib64/python3.12/site-packages/django/db/models/functions/datetime.py", line 353, in convert_value
    raise ValueError(
ValueError: Database returned an invalid datetime value. Are time zone definitions for your database installed?

2024-08-03 16:56:22 [ERROR] DashboardView ERROR: Database returned an invalid datetime value. Are time zone definitions for your database installed? ret:None

2024-08-03 16:56:22 [ERROR] DashboardView ERROR: Database returned an invalid datetime value. Are time zone definitions for your database installed? ret:None

2024-08-03 16:56:22 [ERROR] DashboardView ERROR: Database returned an invalid datetime value. Are time zone definitions for your database installed? ret:None

2024-08-03 16:56:22 [ERROR] 
Traceback (most recent call last):
  File "/data/xadmin/py312/lib64/python3.12/site-packages/rest_framework/views.py", line 506, in dispatch
    response = handler(request, *args, **kwargs)
               ^^^^^^^^^^^^^^^^^^^^^^^^^^^^^^^^^
  File "/data/xadmin/xadmin-server/system/views/dashboard.py", line 54, in user_total
    results, percent, count = trend_info(self.filter_queryset(self.get_queryset()), 7)
                              ^^^^^^^^^^^^^^^^^^^^^^^^^^^^^^^^^^^^^^^^^^^^^^^^^^^^^^^^
  File "/data/xadmin/xadmin-server/system/views/dashboard.py", line 27, in trend_info
    dict_count = {d.get('date').strftime('%m-%d'): d.get('count') for d in data_count}
                 ^^^^^^^^^^^^^^^^^^^^^^^^^^^^^^^^^^^^^^^^^^^^^^^^^^^^^^^^^^^^^^^^^^^^^
  File "/data/xadmin/py312/lib64/python3.12/site-packages/django/db/models/query.py", line 400, in __iter__
    self._fetch_all()
  File "/data/xadmin/py312/lib64/python3.12/site-packages/django/db/models/query.py", line 1928, in _fetch_all
    self._result_cache = list(self._iterable_class(self))
                         ^^^^^^^^^^^^^^^^^^^^^^^^^^^^^^^^
  File "/data/xadmin/py312/lib64/python3.12/site-packages/django/db/models/query.py", line 210, in __iter__
    for row in compiler.results_iter(
  File "/data/xadmin/py312/lib64/python3.12/site-packages/django/db/models/sql/compiler.py", line 1500, in apply_converters
    value = converter(value, expression, connection)
            ^^^^^^^^^^^^^^^^^^^^^^^^^^^^^^^^^^^^^^^^
  File "/data/xadmin/py312/lib64/python3.12/site-packages/django/db/models/functions/datetime.py", line 353, in convert_value
    raise ValueError(
ValueError: Database returned an invalid datetime value. Are time zone definitions for your database installed?

2024-08-03 16:56:22 [ERROR] DashboardView ERROR: Database returned an invalid datetime value. Are time zone definitions for your database installed? ret:None

2024-08-03 16:56:22 [ERROR] 
Traceback (most recent call last):
  File "/data/xadmin/py312/lib64/python3.12/site-packages/rest_framework/views.py", line 506, in dispatch
    response = handler(request, *args, **kwargs)
               ^^^^^^^^^^^^^^^^^^^^^^^^^^^^^^^^^
  File "/data/xadmin/xadmin-server/system/views/dashboard.py", line 63, in user_login_trend
    return ApiResponse(data=trend_info(self.filter_queryset(self.get_queryset()))[0])
                            ^^^^^^^^^^^^^^^^^^^^^^^^^^^^^^^^^^^^^^^^^^^^^^^^^^^^^
  File "/data/xadmin/xadmin-server/system/views/dashboard.py", line 27, in trend_info
    dict_count = {d.get('date').strftime('%m-%d'): d.get('count') for d in data_count}
                 ^^^^^^^^^^^^^^^^^^^^^^^^^^^^^^^^^^^^^^^^^^^^^^^^^^^^^^^^^^^^^^^^^^^^^
  File "/data/xadmin/py312/lib64/python3.12/site-packages/django/db/models/query.py", line 400, in __iter__
    self._fetch_all()
  File "/data/xadmin/py312/lib64/python3.12/site-packages/django/db/models/query.py", line 1928, in _fetch_all
    self._result_cache = list(self._iterable_class(self))
                         ^^^^^^^^^^^^^^^^^^^^^^^^^^^^^^^^
  File "/data/xadmin/py312/lib64/python3.12/site-packages/django/db/models/query.py", line 210, in __iter__
    for row in compiler.results_iter(
  File "/data/xadmin/py312/lib64/python3.12/site-packages/django/db/models/sql/compiler.py", line 1500, in apply_converters
    value = converter(value, expression, connection)
            ^^^^^^^^^^^^^^^^^^^^^^^^^^^^^^^^^^^^^^^^
  File "/data/xadmin/py312/lib64/python3.12/site-packages/django/db/models/functions/datetime.py", line 353, in convert_value
    raise ValueError(
ValueError: Database returned an invalid datetime value. Are time zone definitions for your database installed?

2024-08-03 16:56:22 [ERROR] DashboardView ERROR: Database returned an invalid datetime value. Are time zone definitions for your database installed? ret:None

2024-08-03 16:56:22 [ERROR] DashboardView ERROR: Database returned an invalid datetime value. Are time zone definitions for your database installed? ret:None

2024-08-03 16:56:22 [ERROR] 
Traceback (most recent call last):
  File "/data/xadmin/py312/lib64/python3.12/site-packages/rest_framework/views.py", line 506, in dispatch
    response = handler(request, *args, **kwargs)
               ^^^^^^^^^^^^^^^^^^^^^^^^^^^^^^^^^
  File "/data/xadmin/xadmin-server/system/views/dashboard.py", line 59, in user_registered_trend
    return ApiResponse(data=trend_info(self.filter_queryset(self.get_queryset()))[0])
                            ^^^^^^^^^^^^^^^^^^^^^^^^^^^^^^^^^^^^^^^^^^^^^^^^^^^^^
  File "/data/xadmin/xadmin-server/system/views/dashboard.py", line 27, in trend_info
    dict_count = {d.get('date').strftime('%m-%d'): d.get('count') for d in data_count}
                 ^^^^^^^^^^^^^^^^^^^^^^^^^^^^^^^^^^^^^^^^^^^^^^^^^^^^^^^^^^^^^^^^^^^^^
  File "/data/xadmin/py312/lib64/python3.12/site-packages/django/db/models/query.py", line 400, in __iter__
    self._fetch_all()
  File "/data/xadmin/py312/lib64/python3.12/site-packages/django/db/models/query.py", line 1928, in _fetch_all
    self._result_cache = list(self._iterable_class(self))
                         ^^^^^^^^^^^^^^^^^^^^^^^^^^^^^^^^
  File "/data/xadmin/py312/lib64/python3.12/site-packages/django/db/models/query.py", line 210, in __iter__
    for row in compiler.results_iter(
  File "/data/xadmin/py312/lib64/python3.12/site-packages/django/db/models/sql/compiler.py", line 1500, in apply_converters
    value = converter(value, expression, connection)
            ^^^^^^^^^^^^^^^^^^^^^^^^^^^^^^^^^^^^^^^^
  File "/data/xadmin/py312/lib64/python3.12/site-packages/django/db/models/functions/datetime.py", line 353, in convert_value
    raise ValueError(
ValueError: Database returned an invalid datetime value. Are time zone definitions for your database installed?

2024-08-07 11:53:44 [ERROR] auth failed False
