
2024-08-03 16:56:06 [ERROR] DashboardView ERROR: Database returned an invalid datetime value. Are time zone definitions for your database installed? ret:None

2024-08-03 16:56:06 [ERROR] 
Traceback (most recent call last):
  File "/data/xadmin/py312/lib64/python3.12/site-packages/rest_framework/views.py", line 506, in dispatch
    response = handler(request, *args, **kwargs)
               ^^^^^^^^^^^^^^^^^^^^^^^^^^^^^^^^^
  File "/data/xadmin/xadmin-server/system/views/dashboard.py", line 59, in user_registered_trend
    return ApiResponse(data=trend_info(self.filter_queryset(self.get_queryset()))[0])
                            ^^^^^^^^^^^^^^^^^^^^^^^^^^^^^^^^^^^^^^^^^^^^^^^^^^^^^
  File "/data/xadmin/xadmin-server/system/views/dashboard.py", line 27, in trend_info
    dict_count = {d.get('date').strftime('%m-%d'): d.get('count') for d in data_count}
                 ^^^^^^^^^^^^^^^^^^^^^^^^^^^^^^^^^^^^^^^^^^^^^^^^^^^^^^^^^^^^^^^^^^^^^
  File "/data/xadmin/py312/lib64/python3.12/site-packages/django/db/models/query.py", line 400, in __iter__
    self._fetch_all()
  File "/data/xadmin/py312/lib64/python3.12/site-packages/django/db/models/query.py", line 1928, in _fetch_all
    self._result_cache = list(self._iterable_class(self))
                         ^^^^^^^^^^^^^^^^^^^^^^^^^^^^^^^^
  File "/data/xadmin/py312/lib64/python3.12/site-packages/django/db/models/query.py", line 210, in __iter__
    for row in compiler.results_iter(
  File "/data/xadmin/py312/lib64/python3.12/site-packages/django/db/models/sql/compiler.py", line 1500, in apply_converters
    value = converter(value, expression, connection)
            ^^^^^^^^^^^^^^^^^^^^^^^^^^^^^^^^^^^^^^^^
  File "/data/xadmin/py312/lib64/python3.12/site-packages/django/db/models/functions/datetime.py", line 353, in convert_value
    raise ValueError(
ValueError: Database returned an invalid datetime value. Are time zone definitions for your database installed?

2024-08-03 16:56:06 [ERROR] 
Traceback (most recent call last):
  File "/data/xadmin/py312/lib64/python3.12/site-packages/rest_framework/views.py", line 506, in dispatch
    response = handler(request, *args, **kwargs)
               ^^^^^^^^^^^^^^^^^^^^^^^^^^^^^^^^^
  File "/data/xadmin/xadmin-server/system/views/dashboard.py", line 59, in user_registered_trend
    return ApiResponse(data=trend_info(self.filter_queryset(self.get_queryset()))[0])
                            ^^^^^^^^^^^^^^^^^^^^^^^^^^^^^^^^^^^^^^^^^^^^^^^^^^^^^
  File "/data/xadmin/xadmin-server/system/views/dashboard.py", line 27, in trend_info
    dict_count = {d.get('date').strftime('%m-%d'): d.get('count') for d in data_count}
                 ^^^^^^^^^^^^^^^^^^^^^^^^^^^^^^^^^^^^^^^^^^^^^^^^^^^^^^^^^^^^^^^^^^^^^
  File "/data/xadmin/py312/lib64/python3.12/site-packages/django/db/models/query.py", line 400, in __iter__
    self._fetch_all()
  File "/data/xadmin/py312/lib64/python3.12/site-packages/django/db/models/query.py", line 1928, in _fetch_all
    self._result_cache = list(self._iterable_class(self))
                         ^^^^^^^^^^^^^^^^^^^^^^^^^^^^^^^^
  File "/data/xadmin/py312/lib64/python3.12/site-packages/django/db/models/query.py", line 210, in __iter__
    for row in compiler.results_iter(
  File "/data/xadmin/py312/lib64/python3.12/site-packages/django/db/models/sql/compiler.py", line 1500, in apply_converters
    value = converter(value, expression, connection)
            ^^^^^^^^^^^^^^^^^^^^^^^^^^^^^^^^^^^^^^^^
  File "/data/xadmin/py312/lib64/python3.12/site-packages/django/db/models/functions/datetime.py", line 353, in convert_value
    raise ValueError(
ValueError: Database returned an invalid datetime value. Are time zone definitions for your database installed?

2024-08-03 16:56:06 [ERROR] DashboardView ERROR: Database returned an invalid datetime value. Are time zone definitions for your database installed? ret:None

2024-08-03 16:56:06 [ERROR] 
Traceback (most recent call last):
  File "/data/xadmin/py312/lib64/python3.12/site-packages/rest_framework/views.py", line 506, in dispatch
    response = handler(request, *args, **kwargs)
               ^^^^^^^^^^^^^^^^^^^^^^^^^^^^^^^^^
  File "/data/xadmin/xadmin-server/system/views/dashboard.py", line 54, in user_total
    results, percent, count = trend_info(self.filter_queryset(self.get_queryset()), 7)
                              ^^^^^^^^^^^^^^^^^^^^^^^^^^^^^^^^^^^^^^^^^^^^^^^^^^^^^^^^
  File "/data/xadmin/xadmin-server/system/views/dashboard.py", line 27, in trend_info
    dict_count = {d.get('date').strftime('%m-%d'): d.get('count') for d in data_count}
                 ^^^^^^^^^^^^^^^^^^^^^^^^^^^^^^^^^^^^^^^^^^^^^^^^^^^^^^^^^^^^^^^^^^^^^
  File "/data/xadmin/py312/lib64/python3.12/site-packages/django/db/models/query.py", line 400, in __iter__
    self._fetch_all()
  File "/data/xadmin/py312/lib64/python3.12/site-packages/django/db/models/query.py", line 1928, in _fetch_all
    self._result_cache = list(self._iterable_class(self))
                         ^^^^^^^^^^^^^^^^^^^^^^^^^^^^^^^^
  File "/data/xadmin/py312/lib64/python3.12/site-packages/django/db/models/query.py", line 210, in __iter__
    for row in compiler.results_iter(
  File "/data/xadmin/py312/lib64/python3.12/site-packages/django/db/models/sql/compiler.py", line 1500, in apply_converters
    value = converter(value, expression, connection)
            ^^^^^^^^^^^^^^^^^^^^^^^^^^^^^^^^^^^^^^^^
  File "/data/xadmin/py312/lib64/python3.12/site-packages/django/db/models/functions/datetime.py", line 353, in convert_value
    raise ValueError(
ValueError: Database returned an invalid datetime value. Are time zone definitions for your database installed?

2024-08-03 16:56:06 [ERROR] DashboardView ERROR: Database returned an invalid datetime value. Are time zone definitions for your database installed? ret:None

2024-08-03 16:56:06 [ERROR] 
Traceback (most recent call last):
  File "/data/xadmin/py312/lib64/python3.12/site-packages/rest_framework/views.py", line 506, in dispatch
    response = handler(request, *args, **kwargs)
               ^^^^^^^^^^^^^^^^^^^^^^^^^^^^^^^^^
  File "/data/xadmin/xadmin-server/system/views/dashboard.py", line 49, in user_login_total
    results, percent, count = trend_info(self.filter_queryset(self.get_queryset()), 7)
                              ^^^^^^^^^^^^^^^^^^^^^^^^^^^^^^^^^^^^^^^^^^^^^^^^^^^^^^^^
  File "/data/xadmin/xadmin-server/system/views/dashboard.py", line 27, in trend_info
    dict_count = {d.get('date').strftime('%m-%d'): d.get('count') for d in data_count}
                 ^^^^^^^^^^^^^^^^^^^^^^^^^^^^^^^^^^^^^^^^^^^^^^^^^^^^^^^^^^^^^^^^^^^^^
  File "/data/xadmin/py312/lib64/python3.12/site-packages/django/db/models/query.py", line 400, in __iter__
    self._fetch_all()
  File "/data/xadmin/py312/lib64/python3.12/site-packages/django/db/models/query.py", line 1928, in _fetch_all
    self._result_cache = list(self._iterable_class(self))
                         ^^^^^^^^^^^^^^^^^^^^^^^^^^^^^^^^
  File "/data/xadmin/py312/lib64/python3.12/site-packages/django/db/models/query.py", line 210, in __iter__
    for row in compiler.results_iter(
  File "/data/xadmin/py312/lib64/python3.12/site-packages/django/db/models/sql/compiler.py", line 1500, in apply_converters
    value = converter(value, expression, connection)
            ^^^^^^^^^^^^^^^^^^^^^^^^^^^^^^^^^^^^^^^^
  File "/data/xadmin/py312/lib64/python3.12/site-packages/django/db/models/functions/datetime.py", line 353, in convert_value
    raise ValueError(
ValueError: Database returned an invalid datetime value. Are time zone definitions for your database installed?

2024-08-03 16:56:06 [ERROR] DashboardView ERROR: Database returned an invalid datetime value. Are time zone definitions for your database installed? ret:None

2024-08-03 16:56:06 [ERROR] 
Traceback (most recent call last):
  File "/data/xadmin/py312/lib64/python3.12/site-packages/rest_framework/views.py", line 506, in dispatch
    response = handler(request, *args, **kwargs)
               ^^^^^^^^^^^^^^^^^^^^^^^^^^^^^^^^^
  File "/data/xadmin/xadmin-server/system/views/dashboard.py", line 54, in user_total
    results, percent, count = trend_info(self.filter_queryset(self.get_queryset()), 7)
                              ^^^^^^^^^^^^^^^^^^^^^^^^^^^^^^^^^^^^^^^^^^^^^^^^^^^^^^^^
  File "/data/xadmin/xadmin-server/system/views/dashboard.py", line 27, in trend_info
    dict_count = {d.get('date').strftime('%m-%d'): d.get('count') for d in data_count}
                 ^^^^^^^^^^^^^^^^^^^^^^^^^^^^^^^^^^^^^^^^^^^^^^^^^^^^^^^^^^^^^^^^^^^^^
  File "/data/xadmin/py312/lib64/python3.12/site-packages/django/db/models/query.py", line 400, in __iter__
    self._fetch_all()
  File "/data/xadmin/py312/lib64/python3.12/site-packages/django/db/models/query.py", line 1928, in _fetch_all
    self._result_cache = list(self._iterable_class(self))
                         ^^^^^^^^^^^^^^^^^^^^^^^^^^^^^^^^
  File "/data/xadmin/py312/lib64/python3.12/site-packages/django/db/models/query.py", line 210, in __iter__
    for row in compiler.results_iter(
  File "/data/xadmin/py312/lib64/python3.12/site-packages/django/db/models/sql/compiler.py", line 1500, in apply_converters
    value = converter(value, expression, connection)
            ^^^^^^^^^^^^^^^^^^^^^^^^^^^^^^^^^^^^^^^^
  File "/data/xadmin/py312/lib64/python3.12/site-packages/django/db/models/functions/datetime.py", line 353, in convert_value
    raise ValueError(
ValueError: Database returned an invalid datetime value. Are time zone definitions for your database installed?

2024-08-03 16:56:06 [ERROR] 
Traceback (most recent call last):
  File "/data/xadmin/py312/lib64/python3.12/site-packages/rest_framework/views.py", line 506, in dispatch
    response = handler(request, *args, **kwargs)
               ^^^^^^^^^^^^^^^^^^^^^^^^^^^^^^^^^
  File "/data/xadmin/xadmin-server/system/views/dashboard.py", line 49, in user_login_total
    results, percent, count = trend_info(self.filter_queryset(self.get_queryset()), 7)
                              ^^^^^^^^^^^^^^^^^^^^^^^^^^^^^^^^^^^^^^^^^^^^^^^^^^^^^^^^
  File "/data/xadmin/xadmin-server/system/views/dashboard.py", line 27, in trend_info
    dict_count = {d.get('date').strftime('%m-%d'): d.get('count') for d in data_count}
                 ^^^^^^^^^^^^^^^^^^^^^^^^^^^^^^^^^^^^^^^^^^^^^^^^^^^^^^^^^^^^^^^^^^^^^
  File "/data/xadmin/py312/lib64/python3.12/site-packages/django/db/models/query.py", line 400, in __iter__
    self._fetch_all()
  File "/data/xadmin/py312/lib64/python3.12/site-packages/django/db/models/query.py", line 1928, in _fetch_all
    self._result_cache = list(self._iterable_class(self))
                         ^^^^^^^^^^^^^^^^^^^^^^^^^^^^^^^^
  File "/data/xadmin/py312/lib64/python3.12/site-packages/django/db/models/query.py", line 210, in __iter__
    for row in compiler.results_iter(
  File "/data/xadmin/py312/lib64/python3.12/site-packages/django/db/models/sql/compiler.py", line 1500, in apply_converters
    value = converter(value, expression, connection)
            ^^^^^^^^^^^^^^^^^^^^^^^^^^^^^^^^^^^^^^^^
  File "/data/xadmin/py312/lib64/python3.12/site-packages/django/db/models/functions/datetime.py", line 353, in convert_value
    raise ValueError(
ValueError: Database returned an invalid datetime value. Are time zone definitions for your database installed?

2024-08-03 16:56:06 [ERROR] 
Traceback (most recent call last):
  File "/data/xadmin/py312/lib64/python3.12/site-packages/rest_framework/views.py", line 506, in dispatch
    response = handler(request, *args, **kwargs)
               ^^^^^^^^^^^^^^^^^^^^^^^^^^^^^^^^^
  File "/data/xadmin/xadmin-server/system/views/dashboard.py", line 63, in user_login_trend
    return ApiResponse(data=trend_info(self.filter_queryset(self.get_queryset()))[0])
                            ^^^^^^^^^^^^^^^^^^^^^^^^^^^^^^^^^^^^^^^^^^^^^^^^^^^^^
  File "/data/xadmin/xadmin-server/system/views/dashboard.py", line 27, in trend_info
    dict_count = {d.get('date').strftime('%m-%d'): d.get('count') for d in data_count}
                 ^^^^^^^^^^^^^^^^^^^^^^^^^^^^^^^^^^^^^^^^^^^^^^^^^^^^^^^^^^^^^^^^^^^^^
  File "/data/xadmin/py312/lib64/python3.12/site-packages/django/db/models/query.py", line 400, in __iter__
    self._fetch_all()
  File "/data/xadmin/py312/lib64/python3.12/site-packages/django/db/models/query.py", line 1928, in _fetch_all
    self._result_cache = list(self._iterable_class(self))
                         ^^^^^^^^^^^^^^^^^^^^^^^^^^^^^^^^
  File "/data/xadmin/py312/lib64/python3.12/site-packages/django/db/models/query.py", line 210, in __iter__
    for row in compiler.results_iter(
  File "/data/xadmin/py312/lib64/python3.12/site-packages/django/db/models/sql/compiler.py", line 1500, in apply_converters
    value = converter(value, expression, connection)
            ^^^^^^^^^^^^^^^^^^^^^^^^^^^^^^^^^^^^^^^^
  File "/data/xadmin/py312/lib64/python3.12/site-packages/django/db/models/functions/datetime.py", line 353, in convert_value
    raise ValueError(
ValueError: Database returned an invalid datetime value. Are time zone definitions for your database installed?

2024-08-03 16:56:06 [ERROR] 
Traceback (most recent call last):
  File "/data/xadmin/py312/lib64/python3.12/site-packages/rest_framework/views.py", line 506, in dispatch
    response = handler(request, *args, **kwargs)
               ^^^^^^^^^^^^^^^^^^^^^^^^^^^^^^^^^
  File "/data/xadmin/xadmin-server/system/views/dashboard.py", line 63, in user_login_trend
    return ApiResponse(data=trend_info(self.filter_queryset(self.get_queryset()))[0])
                            ^^^^^^^^^^^^^^^^^^^^^^^^^^^^^^^^^^^^^^^^^^^^^^^^^^^^^
  File "/data/xadmin/xadmin-server/system/views/dashboard.py", line 27, in trend_info
    dict_count = {d.get('date').strftime('%m-%d'): d.get('count') for d in data_count}
                 ^^^^^^^^^^^^^^^^^^^^^^^^^^^^^^^^^^^^^^^^^^^^^^^^^^^^^^^^^^^^^^^^^^^^^
  File "/data/xadmin/py312/lib64/python3.12/site-packages/django/db/models/query.py", line 400, in __iter__
    self._fetch_all()
  File "/data/xadmin/py312/lib64/python3.12/site-packages/django/db/models/query.py", line 1928, in _fetch_all
    self._result_cache = list(self._iterable_class(self))
                         ^^^^^^^^^^^^^^^^^^^^^^^^^^^^^^^^
  File "/data/xadmin/py312/lib64/python3.12/site-packages/django/db/models/query.py", line 210, in __iter__
    for row in compiler.results_iter(
  File "/data/xadmin/py312/lib64/python3.12/site-packages/django/db/models/sql/compiler.py", line 1500, in apply_converters
    value = converter(value, expression, connection)
            ^^^^^^^^^^^^^^^^^^^^^^^^^^^^^^^^^^^^^^^^
  File "/data/xadmin/py312/lib64/python3.12/site-packages/django/db/models/functions/datetime.py", line 353, in convert_value
    raise ValueError(
ValueError: Database returned an invalid datetime value. Are time zone definitions for your database installed?

2024-08-03 16:56:06 [ERROR] DashboardView ERROR: Database returned an invalid datetime value. Are time zone definitions for your database installed? ret:None

2024-08-03 16:56:06 [ERROR] 
Traceback (most recent call last):
  File "/data/xadmin/py312/lib64/python3.12/site-packages/rest_framework/views.py", line 506, in dispatch
    response = handler(request, *args, **kwargs)
               ^^^^^^^^^^^^^^^^^^^^^^^^^^^^^^^^^
  File "/data/xadmin/xadmin-server/system/views/dashboard.py", line 67, in today_operate_total
    results, percent, count = trend_info(self.filter_queryset(self.get_queryset()), 7)
                              ^^^^^^^^^^^^^^^^^^^^^^^^^^^^^^^^^^^^^^^^^^^^^^^^^^^^^^^^
  File "/data/xadmin/xadmin-server/system/views/dashboard.py", line 27, in trend_info
    dict_count = {d.get('date').strftime('%m-%d'): d.get('count') for d in data_count}
                 ^^^^^^^^^^^^^^^^^^^^^^^^^^^^^^^^^^^^^^^^^^^^^^^^^^^^^^^^^^^^^^^^^^^^^
  File "/data/xadmin/py312/lib64/python3.12/site-packages/django/db/models/query.py", line 400, in __iter__
    self._fetch_all()
  File "/data/xadmin/py312/lib64/python3.12/site-packages/django/db/models/query.py", line 1928, in _fetch_all
    self._result_cache = list(self._iterable_class(self))
                         ^^^^^^^^^^^^^^^^^^^^^^^^^^^^^^^^
  File "/data/xadmin/py312/lib64/python3.12/site-packages/django/db/models/query.py", line 210, in __iter__
    for row in compiler.results_iter(
  File "/data/xadmin/py312/lib64/python3.12/site-packages/django/db/models/sql/compiler.py", line 1500, in apply_converters
    value = converter(value, expression, connection)
            ^^^^^^^^^^^^^^^^^^^^^^^^^^^^^^^^^^^^^^^^
  File "/data/xadmin/py312/lib64/python3.12/site-packages/django/db/models/functions/datetime.py", line 353, in convert_value
    raise ValueError(
ValueError: Database returned an invalid datetime value. Are time zone definitions for your database installed?

2024-08-03 16:56:06 [ERROR] 
Traceback (most recent call last):
  File "/data/xadmin/py312/lib64/python3.12/site-packages/rest_framework/views.py", line 506, in dispatch
    response = handler(request, *args, **kwargs)
               ^^^^^^^^^^^^^^^^^^^^^^^^^^^^^^^^^
  File "/data/xadmin/xadmin-server/system/views/dashboard.py", line 67, in today_operate_total
    results, percent, count = trend_info(self.filter_queryset(self.get_queryset()), 7)
                              ^^^^^^^^^^^^^^^^^^^^^^^^^^^^^^^^^^^^^^^^^^^^^^^^^^^^^^^^
  File "/data/xadmin/xadmin-server/system/views/dashboard.py", line 27, in trend_info
    dict_count = {d.get('date').strftime('%m-%d'): d.get('count') for d in data_count}
                 ^^^^^^^^^^^^^^^^^^^^^^^^^^^^^^^^^^^^^^^^^^^^^^^^^^^^^^^^^^^^^^^^^^^^^
  File "/data/xadmin/py312/lib64/python3.12/site-packages/django/db/models/query.py", line 400, in __iter__
    self._fetch_all()
  File "/data/xadmin/py312/lib64/python3.12/site-packages/django/db/models/query.py", line 1928, in _fetch_all
    self._result_cache = list(self._iterable_class(self))
                         ^^^^^^^^^^^^^^^^^^^^^^^^^^^^^^^^
  File "/data/xadmin/py312/lib64/python3.12/site-packages/django/db/models/query.py", line 210, in __iter__
    for row in compiler.results_iter(
  File "/data/xadmin/py312/lib64/python3.12/site-packages/django/db/models/sql/compiler.py", line 1500, in apply_converters
    value = converter(value, expression, connection)
            ^^^^^^^^^^^^^^^^^^^^^^^^^^^^^^^^^^^^^^^^
  File "/data/xadmin/py312/lib64/python3.12/site-packages/django/db/models/functions/datetime.py", line 353, in convert_value
    raise ValueError(
ValueError: Database returned an invalid datetime value. Are time zone definitions for your database installed?

2024-08-03 16:56:22 [ERROR] DashboardView ERROR: Database returned an invalid datetime value. Are time zone definitions for your database installed? ret:None

2024-08-03 16:56:22 [ERROR] 
Traceback (most recent call last):
  File "/data/xadmin/py312/lib64/python3.12/site-packages/rest_framework/views.py", line 506, in dispatch
    response = handler(request, *args, **kwargs)
               ^^^^^^^^^^^^^^^^^^^^^^^^^^^^^^^^^
  File "/data/xadmin/xadmin-server/system/views/dashboard.py", line 67, in today_operate_total
    results, percent, count = trend_info(self.filter_queryset(self.get_queryset()), 7)
                              ^^^^^^^^^^^^^^^^^^^^^^^^^^^^^^^^^^^^^^^^^^^^^^^^^^^^^^^^
  File "/data/xadmin/xadmin-server/system/views/dashboard.py", line 27, in trend_info
    dict_count = {d.get('date').strftime('%m-%d'): d.get('count') for d in data_count}
                 ^^^^^^^^^^^^^^^^^^^^^^^^^^^^^^^^^^^^^^^^^^^^^^^^^^^^^^^^^^^^^^^^^^^^^
  File "/data/xadmin/py312/lib64/python3.12/site-packages/django/db/models/query.py", line 400, in __iter__
    self._fetch_all()
  File "/data/xadmin/py312/lib64/python3.12/site-packages/django/db/models/query.py", line 1928, in _fetch_all
    self._result_cache = list(self._iterable_class(self))
                         ^^^^^^^^^^^^^^^^^^^^^^^^^^^^^^^^
  File "/data/xadmin/py312/lib64/python3.12/site-packages/django/db/models/query.py", line 210, in __iter__
    for row in compiler.results_iter(
  File "/data/xadmin/py312/lib64/python3.12/site-packages/django/db/models/sql/compiler.py", line 1500, in apply_converters
    value = converter(value, expression, connection)
            ^^^^^^^^^^^^^^^^^^^^^^^^^^^^^^^^^^^^^^^^
  File "/data/xadmin/py312/lib64/python3.12/site-packages/django/db/models/functions/datetime.py", line 353, in convert_value
    raise ValueError(
ValueError: Database returned an invalid datetime value. Are time zone definitions for your database installed?

2024-08-03 16:56:22 [ERROR] DashboardView ERROR: Database returned an invalid datetime value. Are time zone definitions for your database installed? ret:None

2024-08-03 16:56:22 [ERROR] 
Traceback (most recent call last):
  File "/data/xadmin/py312/lib64/python3.12/site-packages/rest_framework/views.py", line 506, in dispatch
    response = handler(request, *args, **kwargs)
               ^^^^^^^^^^^^^^^^^^^^^^^^^^^^^^^^^
  File "/data/xadmin/xadmin-server/system/views/dashboard.py", line 67, in today_operate_total
    results, percent, count = trend_info(self.filter_queryset(self.get_queryset()), 7)
                              ^^^^^^^^^^^^^^^^^^^^^^^^^^^^^^^^^^^^^^^^^^^^^^^^^^^^^^^^
  File "/data/xadmin/xadmin-server/system/views/dashboard.py", line 27, in trend_info
    dict_count = {d.get('date').strftime('%m-%d'): d.get('count') for d in data_count}
                 ^^^^^^^^^^^^^^^^^^^^^^^^^^^^^^^^^^^^^^^^^^^^^^^^^^^^^^^^^^^^^^^^^^^^^
  File "/data/xadmin/py312/lib64/python3.12/site-packages/django/db/models/query.py", line 400, in __iter__
    self._fetch_all()
  File "/data/xadmin/py312/lib64/python3.12/site-packages/django/db/models/query.py", line 1928, in _fetch_all
    self._result_cache = list(self._iterable_class(self))
                         ^^^^^^^^^^^^^^^^^^^^^^^^^^^^^^^^
  File "/data/xadmin/py312/lib64/python3.12/site-packages/django/db/models/query.py", line 210, in __iter__
    for row in compiler.results_iter(
  File "/data/xadmin/py312/lib64/python3.12/site-packages/django/db/models/sql/compiler.py", line 1500, in apply_converters
    value = converter(value, expression, connection)
            ^^^^^^^^^^^^^^^^^^^^^^^^^^^^^^^^^^^^^^^^
  File "/data/xadmin/py312/lib64/python3.12/site-packages/django/db/models/functions/datetime.py", line 353, in convert_value
    raise ValueError(
ValueError: Database returned an invalid datetime value. Are time zone definitions for your database installed?

2024-08-03 16:56:22 [ERROR] 
Traceback (most recent call last):
  File "/data/xadmin/py312/lib64/python3.12/site-packages/rest_framework/views.py", line 506, in dispatch
    response = handler(request, *args, **kwargs)
               ^^^^^^^^^^^^^^^^^^^^^^^^^^^^^^^^^
  File "/data/xadmin/xadmin-server/system/views/dashboard.py", line 49, in user_login_total
    results, percent, count = trend_info(self.filter_queryset(self.get_queryset()), 7)
                              ^^^^^^^^^^^^^^^^^^^^^^^^^^^^^^^^^^^^^^^^^^^^^^^^^^^^^^^^
  File "/data/xadmin/xadmin-server/system/views/dashboard.py", line 27, in trend_info
    dict_count = {d.get('date').strftime('%m-%d'): d.get('count') for d in data_count}
                 ^^^^^^^^^^^^^^^^^^^^^^^^^^^^^^^^^^^^^^^^^^^^^^^^^^^^^^^^^^^^^^^^^^^^^
  File "/data/xadmin/py312/lib64/python3.12/site-packages/django/db/models/query.py", line 400, in __iter__
    self._fetch_all()
  File "/data/xadmin/py312/lib64/python3.12/site-packages/django/db/models/query.py", line 1928, in _fetch_all
    self._result_cache = list(self._iterable_class(self))
                         ^^^^^^^^^^^^^^^^^^^^^^^^^^^^^^^^
  File "/data/xadmin/py312/lib64/python3.12/site-packages/django/db/models/query.py", line 210, in __iter__
    for row in compiler.results_iter(
  File "/data/xadmin/py312/lib64/python3.12/site-packages/django/db/models/sql/compiler.py", line 1500, in apply_converters
    value = converter(value, expression, connection)
            ^^^^^^^^^^^^^^^^^^^^^^^^^^^^^^^^^^^^^^^^
  File "/data/xadmin/py312/lib64/python3.12/site-packages/django/db/models/functions/datetime.py", line 353, in convert_value
    raise ValueError(
ValueError: Database returned an invalid datetime value. Are time zone definitions for your database installed?

2024-08-03 16:56:22 [ERROR] 
Traceback (most recent call last):
  File "/data/xadmin/py312/lib64/python3.12/site-packages/rest_framework/views.py", line 506, in dispatch
    response = handler(request, *args, **kwargs)
               ^^^^^^^^^^^^^^^^^^^^^^^^^^^^^^^^^
  File "/data/xadmin/xadmin-server/system/views/dashboard.py", line 49, in user_login_total
    results, percent, count = trend_info(self.filter_queryset(self.get_queryset()), 7)
                              ^^^^^^^^^^^^^^^^^^^^^^^^^^^^^^^^^^^^^^^^^^^^^^^^^^^^^^^^
  File "/data/xadmin/xadmin-server/system/views/dashboard.py", line 27, in trend_info
    dict_count = {d.get('date').strftime('%m-%d'): d.get('count') for d in data_count}
                 ^^^^^^^^^^^^^^^^^^^^^^^^^^^^^^^^^^^^^^^^^^^^^^^^^^^^^^^^^^^^^^^^^^^^^
  File "/data/xadmin/py312/lib64/python3.12/site-packages/django/db/models/query.py", line 400, in __iter__
    self._fetch_all()
  File "/data/xadmin/py312/lib64/python3.12/site-packages/django/db/models/query.py", line 1928, in _fetch_all
    self._result_cache = list(self._iterable_class(self))
                         ^^^^^^^^^^^^^^^^^^^^^^^^^^^^^^^^
  File "/data/xadmin/py312/lib64/python3.12/site-packages/django/db/models/query.py", line 210, in __iter__
    for row in compiler.results_iter(
  File "/data/xadmin/py312/lib64/python3.12/site-packages/django/db/models/sql/compiler.py", line 1500, in apply_converters
    value = converter(value, expression, connection)
            ^^^^^^^^^^^^^^^^^^^^^^^^^^^^^^^^^^^^^^^^
  File "/data/xadmin/py312/lib64/python3.12/site-packages/django/db/models/functions/datetime.py", line 353, in convert_value
    raise ValueError(
ValueError: Database returned an invalid datetime value. Are time zone definitions for your database installed?

2024-08-03 16:56:22 [ERROR] DashboardView ERROR: Database returned an invalid datetime value. Are time zone definitions for your database installed? ret:None

2024-08-03 16:56:22 [ERROR] 
Traceback (most recent call last):
  File "/data/xadmin/py312/lib64/python3.12/site-packages/rest_framework/views.py", line 506, in dispatch
    response = handler(request, *args, **kwargs)
               ^^^^^^^^^^^^^^^^^^^^^^^^^^^^^^^^^
  File "/data/xadmin/xadmin-server/system/views/dashboard.py", line 54, in user_total
    results, percent, count = trend_info(self.filter_queryset(self.get_queryset()), 7)
                              ^^^^^^^^^^^^^^^^^^^^^^^^^^^^^^^^^^^^^^^^^^^^^^^^^^^^^^^^
  File "/data/xadmin/xadmin-server/system/views/dashboard.py", line 27, in trend_info
    dict_count = {d.get('date').strftime('%m-%d'): d.get('count') for d in data_count}
                 ^^^^^^^^^^^^^^^^^^^^^^^^^^^^^^^^^^^^^^^^^^^^^^^^^^^^^^^^^^^^^^^^^^^^^
  File "/data/xadmin/py312/lib64/python3.12/site-packages/django/db/models/query.py", line 400, in __iter__
    self._fetch_all()
  File "/data/xadmin/py312/lib64/python3.12/site-packages/django/db/models/query.py", line 1928, in _fetch_all
    self._result_cache = list(self._iterable_class(self))
                         ^^^^^^^^^^^^^^^^^^^^^^^^^^^^^^^^
  File "/data/xadmin/py312/lib64/python3.12/site-packages/django/db/models/query.py", line 210, in __iter__
    for row in compiler.results_iter(
  File "/data/xadmin/py312/lib64/python3.12/site-packages/django/db/models/sql/compiler.py", line 1500, in apply_converters
    value = converter(value, expression, connection)
            ^^^^^^^^^^^^^^^^^^^^^^^^^^^^^^^^^^^^^^^^
  File "/data/xadmin/py312/lib64/python3.12/site-packages/django/db/models/functions/datetime.py", line 353, in convert_value
    raise ValueError(
ValueError: Database returned an invalid datetime value. Are time zone definitions for your database installed?

2024-08-03 16:56:22 [ERROR] 
Traceback (most recent call last):
  File "/data/xadmin/py312/lib64/python3.12/site-packages/rest_framework/views.py", line 506, in dispatch
    response = handler(request, *args, **kwargs)
               ^^^^^^^^^^^^^^^^^^^^^^^^^^^^^^^^^
  File "/data/xadmin/xadmin-server/system/views/dashboard.py", line 54, in user_total
    results, percent, count = trend_info(self.filter_queryset(self.get_queryset()), 7)
                              ^^^^^^^^^^^^^^^^^^^^^^^^^^^^^^^^^^^^^^^^^^^^^^^^^^^^^^^^
  File "/data/xadmin/xadmin-server/system/views/dashboard.py", line 27, in trend_info
    dict_count = {d.get('date').strftime('%m-%d'): d.get('count') for d in data_count}
                 ^^^^^^^^^^^^^^^^^^^^^^^^^^^^^^^^^^^^^^^^^^^^^^^^^^^^^^^^^^^^^^^^^^^^^
  File "/data/xadmin/py312/lib64/python3.12/site-packages/django/db/models/query.py", line 400, in __iter__
    self._fetch_all()
  File "/data/xadmin/py312/lib64/python3.12/site-packages/django/db/models/query.py", line 1928, in _fetch_all
    self._result_cache = list(self._iterable_class(self))
                         ^^^^^^^^^^^^^^^^^^^^^^^^^^^^^^^^
  File "/data/xadmin/py312/lib64/python3.12/site-packages/django/db/models/query.py", line 210, in __iter__
    for row in compiler.results_iter(
  File "/data/xadmin/py312/lib64/python3.12/site-packages/django/db/models/sql/compiler.py", line 1500, in apply_converters
    value = converter(value, expression, connection)
            ^^^^^^^^^^^^^^^^^^^^^^^^^^^^^^^^^^^^^^^^
  File "/data/xadmin/py312/lib64/python3.12/site-packages/django/db/models/functions/datetime.py", line 353, in convert_value
    raise ValueError(
ValueError: Database returned an invalid datetime value. Are time zone definitions for your database installed?

2024-08-03 16:56:22 [ERROR] DashboardView ERROR: Database returned an invalid datetime value. Are time zone definitions for your database installed? ret:None

2024-08-03 16:56:22 [ERROR] 
Traceback (most recent call last):
  File "/data/xadmin/py312/lib64/python3.12/site-packages/rest_framework/views.py", line 506, in dispatch
    response = handler(request, *args, **kwargs)
               ^^^^^^^^^^^^^^^^^^^^^^^^^^^^^^^^^
  File "/data/xadmin/xadmin-server/system/views/dashboard.py", line 63, in user_login_trend
    return ApiResponse(data=trend_info(self.filter_queryset(self.get_queryset()))[0])
                            ^^^^^^^^^^^^^^^^^^^^^^^^^^^^^^^^^^^^^^^^^^^^^^^^^^^^^
  File "/data/xadmin/xadmin-server/system/views/dashboard.py", line 27, in trend_info
    dict_count = {d.get('date').strftime('%m-%d'): d.get('count') for d in data_count}
                 ^^^^^^^^^^^^^^^^^^^^^^^^^^^^^^^^^^^^^^^^^^^^^^^^^^^^^^^^^^^^^^^^^^^^^
  File "/data/xadmin/py312/lib64/python3.12/site-packages/django/db/models/query.py", line 400, in __iter__
    self._fetch_all()
  File "/data/xadmin/py312/lib64/python3.12/site-packages/django/db/models/query.py", line 1928, in _fetch_all
    self._result_cache = list(self._iterable_class(self))
                         ^^^^^^^^^^^^^^^^^^^^^^^^^^^^^^^^
  File "/data/xadmin/py312/lib64/python3.12/site-packages/django/db/models/query.py", line 210, in __iter__
    for row in compiler.results_iter(
  File "/data/xadmin/py312/lib64/python3.12/site-packages/django/db/models/sql/compiler.py", line 1500, in apply_converters
    value = converter(value, expression, connection)
            ^^^^^^^^^^^^^^^^^^^^^^^^^^^^^^^^^^^^^^^^
  File "/data/xadmin/py312/lib64/python3.12/site-packages/django/db/models/functions/datetime.py", line 353, in convert_value
    raise ValueError(
ValueError: Database returned an invalid datetime value. Are time zone definitions for your database installed?

2024-08-03 16:56:22 [ERROR] 
Traceback (most recent call last):
  File "/data/xadmin/py312/lib64/python3.12/site-packages/rest_framework/views.py", line 506, in dispatch
    response = handler(request, *args, **kwargs)
               ^^^^^^^^^^^^^^^^^^^^^^^^^^^^^^^^^
  File "/data/xadmin/xadmin-server/system/views/dashboard.py", line 63, in user_login_trend
    return ApiResponse(data=trend_info(self.filter_queryset(self.get_queryset()))[0])
                            ^^^^^^^^^^^^^^^^^^^^^^^^^^^^^^^^^^^^^^^^^^^^^^^^^^^^^
  File "/data/xadmin/xadmin-server/system/views/dashboard.py", line 27, in trend_info
    dict_count = {d.get('date').strftime('%m-%d'): d.get('count') for d in data_count}
                 ^^^^^^^^^^^^^^^^^^^^^^^^^^^^^^^^^^^^^^^^^^^^^^^^^^^^^^^^^^^^^^^^^^^^^
  File "/data/xadmin/py312/lib64/python3.12/site-packages/django/db/models/query.py", line 400, in __iter__
    self._fetch_all()
  File "/data/xadmin/py312/lib64/python3.12/site-packages/django/db/models/query.py", line 1928, in _fetch_all
    self._result_cache = list(self._iterable_class(self))
                         ^^^^^^^^^^^^^^^^^^^^^^^^^^^^^^^^
  File "/data/xadmin/py312/lib64/python3.12/site-packages/django/db/models/query.py", line 210, in __iter__
    for row in compiler.results_iter(
  File "/data/xadmin/py312/lib64/python3.12/site-packages/django/db/models/sql/compiler.py", line 1500, in apply_converters
    value = converter(value, expression, connection)
            ^^^^^^^^^^^^^^^^^^^^^^^^^^^^^^^^^^^^^^^^
  File "/data/xadmin/py312/lib64/python3.12/site-packages/django/db/models/functions/datetime.py", line 353, in convert_value
    raise ValueError(
ValueError: Database returned an invalid datetime value. Are time zone definitions for your database installed?

2024-08-03 16:56:22 [ERROR] DashboardView ERROR: Database returned an invalid datetime value. Are time zone definitions for your database installed? ret:None

2024-08-03 16:56:22 [ERROR] 
Traceback (most recent call last):
  File "/data/xadmin/py312/lib64/python3.12/site-packages/rest_framework/views.py", line 506, in dispatch
    response = handler(request, *args, **kwargs)
               ^^^^^^^^^^^^^^^^^^^^^^^^^^^^^^^^^
  File "/data/xadmin/xadmin-server/system/views/dashboard.py", line 59, in user_registered_trend
    return ApiResponse(data=trend_info(self.filter_queryset(self.get_queryset()))[0])
                            ^^^^^^^^^^^^^^^^^^^^^^^^^^^^^^^^^^^^^^^^^^^^^^^^^^^^^
  File "/data/xadmin/xadmin-server/system/views/dashboard.py", line 27, in trend_info
    dict_count = {d.get('date').strftime('%m-%d'): d.get('count') for d in data_count}
                 ^^^^^^^^^^^^^^^^^^^^^^^^^^^^^^^^^^^^^^^^^^^^^^^^^^^^^^^^^^^^^^^^^^^^^
  File "/data/xadmin/py312/lib64/python3.12/site-packages/django/db/models/query.py", line 400, in __iter__
    self._fetch_all()
  File "/data/xadmin/py312/lib64/python3.12/site-packages/django/db/models/query.py", line 1928, in _fetch_all
    self._result_cache = list(self._iterable_class(self))
                         ^^^^^^^^^^^^^^^^^^^^^^^^^^^^^^^^
  File "/data/xadmin/py312/lib64/python3.12/site-packages/django/db/models/query.py", line 210, in __iter__
    for row in compiler.results_iter(
  File "/data/xadmin/py312/lib64/python3.12/site-packages/django/db/models/sql/compiler.py", line 1500, in apply_converters
    value = converter(value, expression, connection)
            ^^^^^^^^^^^^^^^^^^^^^^^^^^^^^^^^^^^^^^^^
  File "/data/xadmin/py312/lib64/python3.12/site-packages/django/db/models/functions/datetime.py", line 353, in convert_value
    raise ValueError(
ValueError: Database returned an invalid datetime value. Are time zone definitions for your database installed?

2024-08-03 16:56:22 [ERROR] 
Traceback (most recent call last):
  File "/data/xadmin/py312/lib64/python3.12/site-packages/rest_framework/views.py", line 506, in dispatch
    response = handler(request, *args, **kwargs)
               ^^^^^^^^^^^^^^^^^^^^^^^^^^^^^^^^^
  File "/data/xadmin/xadmin-server/system/views/dashboard.py", line 59, in user_registered_trend
    return ApiResponse(data=trend_info(self.filter_queryset(self.get_queryset()))[0])
                            ^^^^^^^^^^^^^^^^^^^^^^^^^^^^^^^^^^^^^^^^^^^^^^^^^^^^^
  File "/data/xadmin/xadmin-server/system/views/dashboard.py", line 27, in trend_info
    dict_count = {d.get('date').strftime('%m-%d'): d.get('count') for d in data_count}
                 ^^^^^^^^^^^^^^^^^^^^^^^^^^^^^^^^^^^^^^^^^^^^^^^^^^^^^^^^^^^^^^^^^^^^^
  File "/data/xadmin/py312/lib64/python3.12/site-packages/django/db/models/query.py", line 400, in __iter__
    self._fetch_all()
  File "/data/xadmin/py312/lib64/python3.12/site-packages/django/db/models/query.py", line 1928, in _fetch_all
    self._result_cache = list(self._iterable_class(self))
                         ^^^^^^^^^^^^^^^^^^^^^^^^^^^^^^^^
  File "/data/xadmin/py312/lib64/python3.12/site-packages/django/db/models/query.py", line 210, in __iter__
    for row in compiler.results_iter(
  File "/data/xadmin/py312/lib64/python3.12/site-packages/django/db/models/sql/compiler.py", line 1500, in apply_converters
    value = converter(value, expression, connection)
            ^^^^^^^^^^^^^^^^^^^^^^^^^^^^^^^^^^^^^^^^
  File "/data/xadmin/py312/lib64/python3.12/site-packages/django/db/models/functions/datetime.py", line 353, in convert_value
    raise ValueError(
ValueError: Database returned an invalid datetime value. Are time zone definitions for your database installed?

2024-08-07 11:53:44 [ERROR] auth failed False

2024-08-23 13:30:12 [ERROR] FreightBillView ERROR: {'detail': ErrorDetail(string='此令牌对任何类型的令牌无效', code='token_not_valid'), 'code': ErrorDetail(string='token_not_valid', code='token_not_valid'), 'messages': [{'token_class': ErrorDetail(string='ServerAccessToken', code='token_not_valid'), 'token_type': ErrorDetail(string='access', code='token_not_valid'), 'message': ErrorDetail(string='令牌无效或过期', code='token_not_valid')}]} ret:<Response status_code=401, "text/html; charset=utf-8">

2024-08-26 08:40:07 [ERROR] verify_token token:tmp_token_f3c859a5563851b0a044fb88f074c1655e295632634111efb8ec  key:TW96aWxsYS81LjAgKFdpbmRvd3MgTlQgMTAuMDsgV2luNjQ7IHg2NCkgQXBwbGVXZWJLaXQvNTM3LjM2IChLSFRNTCwgbGlrZSBHZWNrbykgQ2hyb21lLzEyMi4wLjYyNjEuOTUgU2FmYXJpLzUzNy4zNmFwcGxpY2F0aW9uL2pzb24sIHRleHQvcGxhaW4sICovKjEyNy4wLjAuMQ== failed

2024-09-20 15:40:29 [ERROR] verify_token token:tmp_token_f3c859a5563851b0a044fb88f074c1654d8edad2771811efae2b  key:TW96aWxsYS81LjAgKFdpbmRvd3MgTlQgMTAuMDsgV2luNjQ7IHg2NCkgQXBwbGVXZWJLaXQvNTM3LjM2IChLSFRNTCwgbGlrZSBHZWNrbykgQ2hyb21lLzEyMi4wLjYyNjEuOTUgU2FmYXJpLzUzNy4zNmFwcGxpY2F0aW9uL2pzb24sIHRleHQvcGxhaW4sICovKjEyNy4wLjAuMQ== failed

2024-09-21 15:52:13 [ERROR] BookView ERROR: {'detail': ErrorDetail(string='Given token not valid for any token type', code='token_not_valid'), 'code': ErrorDetail(string='token_not_valid', code='token_not_valid'), 'messages': [{'token_class': ErrorDetail(string='ServerAccessToken', code='token_not_valid'), 'token_type': ErrorDetail(string='access', code='token_not_valid'), 'message': ErrorDetail(string='Token is invalid or expired', code='token_not_valid')}]} ret:<Response status_code=401, "text/html; charset=utf-8">

2024-09-21 15:53:20 [ERROR] BookView ERROR: {'detail': ErrorDetail(string='Given token not valid for any token type', code='token_not_valid'), 'code': ErrorDetail(string='token_not_valid', code='token_not_valid'), 'messages': [{'token_class': ErrorDetail(string='ServerAccessToken', code='token_not_valid'), 'token_type': ErrorDetail(string='access', code='token_not_valid'), 'message': ErrorDetail(string='Token is invalid or expired', code='token_not_valid')}]} ret:<Response status_code=401, "text/html; charset=utf-8">

2024-09-21 16:20:18 [ERROR] verify_token token:55e290faecd45ed992f3c7b356a1b1bb2dfe79c277f211ef9916  key:Y3VybC83Ljc2LjEqLyoxMC4yLjMuMTEw failed

2024-10-07 16:43:54 [ERROR] BasicLoginView ERROR: 图片验证码校验失败，请稍后重试 ret:<Response status_code=500, "text/html; charset=utf-8">

2024-10-07 16:44:01 [ERROR] BasicLoginView ERROR: (1054, "Unknown column 'city' in 'field list'") ret:None

2024-10-07 16:44:01 [ERROR] 
Traceback (most recent call last):
  File "/data/xadmin/py312/lib64/python3.12/site-packages/django/db/backends/utils.py", line 105, in _execute
    return self.cursor.execute(sql, params)
           ^^^^^^^^^^^^^^^^^^^^^^^^^^^^^^^^
  File "/data/xadmin/py312/lib64/python3.12/site-packages/django/db/backends/mysql/base.py", line 76, in execute
    return self.cursor.execute(query, args)
           ^^^^^^^^^^^^^^^^^^^^^^^^^^^^^^^^
  File "/data/xadmin/py312/lib64/python3.12/site-packages/MySQLdb/cursors.py", line 179, in execute
    res = self._query(mogrified_query)
          ^^^^^^^^^^^^^^^^^^^^^^^^^^^^
  File "/data/xadmin/py312/lib64/python3.12/site-packages/MySQLdb/cursors.py", line 330, in _query
    db.query(q)
  File "/data/xadmin/py312/lib64/python3.12/site-packages/MySQLdb/connections.py", line 261, in query
    _mysql.connection.query(self, query)
MySQLdb.OperationalError: (1054, "Unknown column 'city' in 'field list'")

The above exception was the direct cause of the following exception:

Traceback (most recent call last):
  File "/data/xadmin/py312/lib64/python3.12/site-packages/rest_framework/views.py", line 506, in dispatch
    response = handler(request, *args, **kwargs)
               ^^^^^^^^^^^^^^^^^^^^^^^^^^^^^^^^^
  File "/data/xadmin/xadmin-server/system/views/auth/login.py", line 114, in post
    login_success(request, serializer.user)
  File "/data/xadmin/xadmin-server/system/views/auth/login.py", line 61, in login_success
    save_login_log(request, login_type=login_type)
  File "/data/xadmin/xadmin-server/system/utils/auth.py", line 94, in save_login_log
    serializer.save()
  File "/data/xadmin/py312/lib64/python3.12/site-packages/rest_framework/serializers.py", line 208, in save
    self.instance = self.create(validated_data)
                    ^^^^^^^^^^^^^^^^^^^^^^^^^^^
  File "/data/xadmin/xadmin-server/common/core/serializers.py", line 111, in create
    return super().create(validated_data)
           ^^^^^^^^^^^^^^^^^^^^^^^^^^^^^^
  File "/data/xadmin/py312/lib64/python3.12/site-packages/rest_framework/serializers.py", line 989, in create
    instance = ModelClass._default_manager.create(**validated_data)
               ^^^^^^^^^^^^^^^^^^^^^^^^^^^^^^^^^^^^^^^^^^^^^^^^^^^^
  File "/data/xadmin/py312/lib64/python3.12/site-packages/django/db/models/manager.py", line 87, in manager_method
    return getattr(self.get_queryset(), name)(*args, **kwargs)
           ^^^^^^^^^^^^^^^^^^^^^^^^^^^^^^^^^^^^^^^^^^^^^^^^^^^
  File "/data/xadmin/py312/lib64/python3.12/site-packages/django/db/models/query.py", line 679, in create
    obj.save(force_insert=True, using=self.db)
  File "/data/xadmin/xadmin-server/common/core/models.py", line 43, in save
    result = super().save(*args, **kwargs)
             ^^^^^^^^^^^^^^^^^^^^^^^^^^^^^
  File "/data/xadmin/py312/lib64/python3.12/site-packages/django/db/models/base.py", line 891, in save
    self.save_base(
  File "/data/xadmin/py312/lib64/python3.12/site-packages/django/db/models/base.py", line 997, in save_base
    updated = self._save_table(
              ^^^^^^^^^^^^^^^^^
  File "/data/xadmin/py312/lib64/python3.12/site-packages/django/db/models/base.py", line 1160, in _save_table
    results = self._do_insert(
              ^^^^^^^^^^^^^^^^
  File "/data/xadmin/py312/lib64/python3.12/site-packages/django/db/models/base.py", line 1201, in _do_insert
    return manager._insert(
           ^^^^^^^^^^^^^^^^
  File "/data/xadmin/py312/lib64/python3.12/site-packages/django/db/models/manager.py", line 87, in manager_method
    return getattr(self.get_queryset(), name)(*args, **kwargs)
           ^^^^^^^^^^^^^^^^^^^^^^^^^^^^^^^^^^^^^^^^^^^^^^^^^^^
  File "/data/xadmin/py312/lib64/python3.12/site-packages/django/db/models/query.py", line 1847, in _insert
    return query.get_compiler(using=using).execute_sql(returning_fields)
           ^^^^^^^^^^^^^^^^^^^^^^^^^^^^^^^^^^^^^^^^^^^^^^^^^^^^^^^^^^^^^
  File "/data/xadmin/py312/lib64/python3.12/site-packages/django/db/models/sql/compiler.py", line 1836, in execute_sql
    cursor.execute(sql, params)
  File "/data/xadmin/py312/lib64/python3.12/site-packages/django/db/backends/utils.py", line 79, in execute
    return self._execute_with_wrappers(
           ^^^^^^^^^^^^^^^^^^^^^^^^^^^^
  File "/data/xadmin/py312/lib64/python3.12/site-packages/django/db/backends/utils.py", line 92, in _execute_with_wrappers
    return executor(sql, params, many, context)
           ^^^^^^^^^^^^^^^^^^^^^^^^^^^^^^^^^^^^
  File "/data/xadmin/py312/lib64/python3.12/site-packages/django/db/backends/utils.py", line 100, in _execute
    with self.db.wrap_database_errors:
  File "/data/xadmin/py312/lib64/python3.12/site-packages/django/db/utils.py", line 91, in __exit__
    raise dj_exc_value.with_traceback(traceback) from exc_value
  File "/data/xadmin/py312/lib64/python3.12/site-packages/django/db/backends/utils.py", line 105, in _execute
    return self.cursor.execute(sql, params)
           ^^^^^^^^^^^^^^^^^^^^^^^^^^^^^^^^
  File "/data/xadmin/py312/lib64/python3.12/site-packages/django/db/backends/mysql/base.py", line 76, in execute
    return self.cursor.execute(query, args)
           ^^^^^^^^^^^^^^^^^^^^^^^^^^^^^^^^
  File "/data/xadmin/py312/lib64/python3.12/site-packages/MySQLdb/cursors.py", line 179, in execute
    res = self._query(mogrified_query)
          ^^^^^^^^^^^^^^^^^^^^^^^^^^^^
  File "/data/xadmin/py312/lib64/python3.12/site-packages/MySQLdb/cursors.py", line 330, in _query
    db.query(q)
  File "/data/xadmin/py312/lib64/python3.12/site-packages/MySQLdb/connections.py", line 261, in query
    _mysql.connection.query(self, query)
django.db.utils.OperationalError: (1054, "Unknown column 'city' in 'field list'")

2024-10-07 16:44:01 [ERROR] 
Traceback (most recent call last):
  File "/data/xadmin/py312/lib64/python3.12/site-packages/django/db/backends/utils.py", line 105, in _execute
    return self.cursor.execute(sql, params)
           ^^^^^^^^^^^^^^^^^^^^^^^^^^^^^^^^
  File "/data/xadmin/py312/lib64/python3.12/site-packages/django/db/backends/mysql/base.py", line 76, in execute
    return self.cursor.execute(query, args)
           ^^^^^^^^^^^^^^^^^^^^^^^^^^^^^^^^
  File "/data/xadmin/py312/lib64/python3.12/site-packages/MySQLdb/cursors.py", line 179, in execute
    res = self._query(mogrified_query)
          ^^^^^^^^^^^^^^^^^^^^^^^^^^^^
  File "/data/xadmin/py312/lib64/python3.12/site-packages/MySQLdb/cursors.py", line 330, in _query
    db.query(q)
  File "/data/xadmin/py312/lib64/python3.12/site-packages/MySQLdb/connections.py", line 261, in query
    _mysql.connection.query(self, query)
MySQLdb.OperationalError: (1054, "Unknown column 'city' in 'field list'")

The above exception was the direct cause of the following exception:

Traceback (most recent call last):
  File "/data/xadmin/py312/lib64/python3.12/site-packages/rest_framework/views.py", line 506, in dispatch
    response = handler(request, *args, **kwargs)
               ^^^^^^^^^^^^^^^^^^^^^^^^^^^^^^^^^
  File "/data/xadmin/xadmin-server/system/views/auth/login.py", line 114, in post
    login_success(request, serializer.user)
  File "/data/xadmin/xadmin-server/system/views/auth/login.py", line 61, in login_success
    save_login_log(request, login_type=login_type)
  File "/data/xadmin/xadmin-server/system/utils/auth.py", line 94, in save_login_log
    serializer.save()
  File "/data/xadmin/py312/lib64/python3.12/site-packages/rest_framework/serializers.py", line 208, in save
    self.instance = self.create(validated_data)
                    ^^^^^^^^^^^^^^^^^^^^^^^^^^^
  File "/data/xadmin/xadmin-server/common/core/serializers.py", line 111, in create
    return super().create(validated_data)
           ^^^^^^^^^^^^^^^^^^^^^^^^^^^^^^
  File "/data/xadmin/py312/lib64/python3.12/site-packages/rest_framework/serializers.py", line 989, in create
    instance = ModelClass._default_manager.create(**validated_data)
               ^^^^^^^^^^^^^^^^^^^^^^^^^^^^^^^^^^^^^^^^^^^^^^^^^^^^
  File "/data/xadmin/py312/lib64/python3.12/site-packages/django/db/models/manager.py", line 87, in manager_method
    return getattr(self.get_queryset(), name)(*args, **kwargs)
           ^^^^^^^^^^^^^^^^^^^^^^^^^^^^^^^^^^^^^^^^^^^^^^^^^^^
  File "/data/xadmin/py312/lib64/python3.12/site-packages/django/db/models/query.py", line 679, in create
    obj.save(force_insert=True, using=self.db)
  File "/data/xadmin/xadmin-server/common/core/models.py", line 43, in save
    result = super().save(*args, **kwargs)
             ^^^^^^^^^^^^^^^^^^^^^^^^^^^^^
  File "/data/xadmin/py312/lib64/python3.12/site-packages/django/db/models/base.py", line 891, in save
    self.save_base(
  File "/data/xadmin/py312/lib64/python3.12/site-packages/django/db/models/base.py", line 997, in save_base
    updated = self._save_table(
              ^^^^^^^^^^^^^^^^^
  File "/data/xadmin/py312/lib64/python3.12/site-packages/django/db/models/base.py", line 1160, in _save_table
    results = self._do_insert(
              ^^^^^^^^^^^^^^^^
  File "/data/xadmin/py312/lib64/python3.12/site-packages/django/db/models/base.py", line 1201, in _do_insert
    return manager._insert(
           ^^^^^^^^^^^^^^^^
  File "/data/xadmin/py312/lib64/python3.12/site-packages/django/db/models/manager.py", line 87, in manager_method
    return getattr(self.get_queryset(), name)(*args, **kwargs)
           ^^^^^^^^^^^^^^^^^^^^^^^^^^^^^^^^^^^^^^^^^^^^^^^^^^^
  File "/data/xadmin/py312/lib64/python3.12/site-packages/django/db/models/query.py", line 1847, in _insert
    return query.get_compiler(using=using).execute_sql(returning_fields)
           ^^^^^^^^^^^^^^^^^^^^^^^^^^^^^^^^^^^^^^^^^^^^^^^^^^^^^^^^^^^^^
  File "/data/xadmin/py312/lib64/python3.12/site-packages/django/db/models/sql/compiler.py", line 1836, in execute_sql
    cursor.execute(sql, params)
  File "/data/xadmin/py312/lib64/python3.12/site-packages/django/db/backends/utils.py", line 79, in execute
    return self._execute_with_wrappers(
           ^^^^^^^^^^^^^^^^^^^^^^^^^^^^
  File "/data/xadmin/py312/lib64/python3.12/site-packages/django/db/backends/utils.py", line 92, in _execute_with_wrappers
    return executor(sql, params, many, context)
           ^^^^^^^^^^^^^^^^^^^^^^^^^^^^^^^^^^^^
  File "/data/xadmin/py312/lib64/python3.12/site-packages/django/db/backends/utils.py", line 100, in _execute
    with self.db.wrap_database_errors:
  File "/data/xadmin/py312/lib64/python3.12/site-packages/django/db/utils.py", line 91, in __exit__
    raise dj_exc_value.with_traceback(traceback) from exc_value
  File "/data/xadmin/py312/lib64/python3.12/site-packages/django/db/backends/utils.py", line 105, in _execute
    return self.cursor.execute(sql, params)
           ^^^^^^^^^^^^^^^^^^^^^^^^^^^^^^^^
  File "/data/xadmin/py312/lib64/python3.12/site-packages/django/db/backends/mysql/base.py", line 76, in execute
    return self.cursor.execute(query, args)
           ^^^^^^^^^^^^^^^^^^^^^^^^^^^^^^^^
  File "/data/xadmin/py312/lib64/python3.12/site-packages/MySQLdb/cursors.py", line 179, in execute
    res = self._query(mogrified_query)
          ^^^^^^^^^^^^^^^^^^^^^^^^^^^^
  File "/data/xadmin/py312/lib64/python3.12/site-packages/MySQLdb/cursors.py", line 330, in _query
    db.query(q)
  File "/data/xadmin/py312/lib64/python3.12/site-packages/MySQLdb/connections.py", line 261, in query
    _mysql.connection.query(self, query)
django.db.utils.OperationalError: (1054, "Unknown column 'city' in 'field list'")
